2021-02-12 15:02:35 ERROR (MainThread) [aiohttp.server] Unhandled exception
Traceback (most recent call last):
  File "/usr/local/lib/python3.8/site-packages/aiohttp/web_protocol.py", line 485, in start
    resp, reset = await task
  File "/usr/local/lib/python3.8/site-packages/aiohttp/web_protocol.py", line 440, in _handle_request
    reset = await self.finish_response(request, resp, start_time)
  File "/usr/local/lib/python3.8/site-packages/aiohttp/web_protocol.py", line 591, in finish_response
    await prepare_meth(request)
  File "/usr/local/lib/python3.8/site-packages/aiohttp/web_fileresponse.py", line 115, in prepare
    st = await loop.run_in_executor(None, filepath.stat)
  File "/usr/local/lib/python3.8/concurrent/futures/thread.py", line 57, in run
    result = self.fn(*self.args, **self.kwargs)
  File "/usr/local/lib/python3.8/pathlib.py", line 1197, in stat
    return self._accessor.stat(self)
FileNotFoundError: [Errno 2] No such file or directory: '/config/home-assistant.log'
2021-02-12 15:19:24 ERROR (Thread-13) [homeassistant.components.cast.media_player] Failed to cast media https://www.home-assistant.io/images/cast/splash.png. Please make sure the URL is: Reachable from the cast device and either a publicly resolvable hostname or an IP address
2021-02-12 15:35:12 ERROR (MainThread) [homeassistant.components.upnp] Timeout fetching VMG3926-B10A data
2021-02-12 15:36:27 ERROR (MainThread) [homeassistant.components.upnp] Timeout fetching VMG3926-B10A data
